Traceback (most recent call last):
  File "C:\Users\julia\miniconda3\lib\site-packages\jupyter_cache\executors\utils.py", line 51, in single_nb_execution
    executenb(
  File "C:\Users\julia\miniconda3\lib\site-packages\nbclient\client.py", line 1204, in execute
    return NotebookClient(nb=nb, resources=resources, km=km, **kwargs).execute()
  File "C:\Users\julia\miniconda3\lib\site-packages\nbclient\util.py", line 84, in wrapped
    return just_run(coro(*args, **kwargs))
  File "C:\Users\julia\miniconda3\lib\site-packages\nbclient\util.py", line 62, in just_run
    return loop.run_until_complete(coro)
  File "C:\Users\julia\miniconda3\lib\asyncio\base_events.py", line 647, in run_until_complete
    return future.result()
  File "C:\Users\julia\miniconda3\lib\site-packages\nbclient\client.py", line 663, in async_execute
    await self.async_execute_cell(
  File "C:\Users\julia\miniconda3\lib\site-packages\nbclient\client.py", line 965, in async_execute_cell
    await self._check_raise_for_error(cell, cell_index, exec_reply)
  File "C:\Users\julia\miniconda3\lib\site-packages\nbclient\client.py", line 862, in _check_raise_for_error
    raise CellExecutionError.from_cell_and_msg(cell, exec_reply_content)
nbclient.exceptions.CellExecutionError: An error occurred while executing the following cell:
------------------
def sum_lists(list1 , list2):    #functionalities are defined for generalized usability and can be imported into other files
    return sum(list1) + sum(list2)

def read_floats_from_file(filename):
    with open(filename , "r") as in_file:
         lines = in_file.readlines ()
    float_list = []
    for line in lines:
        float_list.append(float(line.strip ()))
    return float_list

if __name__ == "__main__": #input is read in only here, that is, when executing the source file as standalone program.
    l1 = read_floats_from_file("test.txt")
    l2 = read_floats_from_file("test2.txt")
    print("Sum of both lists: " + str(sum_lists(l1 ,l2)))
------------------

[1;31m---------------------------------------------------------------------------[0m
[1;31mValueError[0m                                Traceback (most recent call last)
[1;32m~\AppData\Local\Temp\ipykernel_10600\3358627449.py[0m in [0;36m<module>[1;34m[0m
[0;32m     11[0m [1;33m[0m[0m
[0;32m     12[0m [1;32mif[0m [0m__name__[0m [1;33m==[0m [1;34m"__main__"[0m[1;33m:[0m [1;31m#input is read in only here, that is, when executing the source file as standalone program.[0m[1;33m[0m[1;33m[0m[0m
[1;32m---> 13[1;33m     [0ml1[0m [1;33m=[0m [0mread_floats_from_file[0m[1;33m([0m[1;34m"test.txt"[0m[1;33m)[0m[1;33m[0m[1;33m[0m[0m
[0m[0;32m     14[0m     [0ml2[0m [1;33m=[0m [0mread_floats_from_file[0m[1;33m([0m[1;34m"test2.txt"[0m[1;33m)[0m[1;33m[0m[1;33m[0m[0m
[0;32m     15[0m     [0mprint[0m[1;33m([0m[1;34m"Sum of both lists: "[0m [1;33m+[0m [0mstr[0m[1;33m([0m[0msum_lists[0m[1;33m([0m[0ml1[0m [1;33m,[0m[0ml2[0m[1;33m)[0m[1;33m)[0m[1;33m)[0m[1;33m[0m[1;33m[0m[0m

[1;32m~\AppData\Local\Temp\ipykernel_10600\3358627449.py[0m in [0;36mread_floats_from_file[1;34m(filename)[0m
[0;32m      7[0m     [0mfloat_list[0m [1;33m=[0m [1;33m[[0m[1;33m][0m[1;33m[0m[1;33m[0m[0m
[0;32m      8[0m     [1;32mfor[0m [0mline[0m [1;32min[0m [0mlines[0m[1;33m:[0m[1;33m[0m[1;33m[0m[0m
[1;32m----> 9[1;33m         [0mfloat_list[0m[1;33m.[0m[0mappend[0m[1;33m([0m[0mfloat[0m[1;33m([0m[0mline[0m[1;33m.[0m[0mstrip[0m [1;33m([0m[1;33m)[0m[1;33m)[0m[1;33m)[0m[1;33m[0m[1;33m[0m[0m
[0m[0;32m     10[0m     [1;32mreturn[0m [0mfloat_list[0m[1;33m[0m[1;33m[0m[0m
[0;32m     11[0m [1;33m[0m[0m

[1;31mValueError[0m: could not convert string to float: 'hello world'
ValueError: could not convert string to float: 'hello world'

